Workbook

Sheet Final_Summary
A1: Project 1: India General Insurance Claims & Pricing Performance Dashboard
A4: 1. Project Objective & Business Problem
A5: This project analyses premium growth, claim pressure and pricing adequacy signals across Indian general insurance segments using public data. The main business problem is that premium growth alone does not prove profitability. A segment may grow strongly but still face high claims, commission load, expense load or pricing pressure.
A10: 2. Data Sources Used
A11: 1. GI Council Segment-wise GDPI data — used for segment premium growth and insurer ranking. 2. IRDAI Annual Report 2024-25 Table I.14 — used for incurred claims ratio and claim-pressure interpretation. 3. ICICI Lombard NL-4, NL-5, NL-6 and NL-7 public disclosures — used for premium, claims, commission and operating expense analysis.
A17: 3. Methodology
A18: The workflow followed a professional analysis chain: source collection → raw extraction → cleaned data → pivot analysis → segment premium growth analysis → insurer ranking → IRDAI ICR claim-pressure layer → ICICI Lombard pricing mini-case → Excel dashboard with KPI cards, charts, executive insights and source note.
A24: 4. Key Findings
A25: 1. Selected segment premium increased from ₹29,143.19 Cr in Apr-25 to ₹31,654.17 Cr in Apr-26, showing 8.62% growth. 2. Health is the largest selected segment and grew 21.61%, while Marine grew fastest at 33.63% from a smaller base. 3. Fire declined by 30.92%, so it should not be judged only by premium fall; claim pressure and portfolio mix must also be checked. 4. Motor ICR is 85.51% and Health ICR is 85.34%, showing high claim-pressure signals. 5. ICICI Lombard’s disclosed company-level analytical combined load indicator is 104.98%, suggesting pricing-load pressure before full P&L and investment income analysis.
A35: 5. Recommendations
A36: 1. Do not judge general insurance performance only by premium growth; premium movement must be connected with ICR, claims, commission load and expense load. 2. Motor and Health should be monitored closely because both show high claim-pressure signals despite being important business segments. 3. Insurer premium ranking should be treated as a market-volume indicator, not a direct profitability ranking.
A43: 6. Limitations & Correct Interpretation
... A52: This workbook includes the complete Project 1 workflow: source log, raw data extraction, cleaned data, pivot analysis, claim-pressure analysis, ICICI Lombard pricing mini-case, dashboard and executive summary. The dashboard can be used as the main presentation output, while the backend sheets support auditability and interview explanation.

Sheet Dashboard_Draft
A1: India General Insurance Claims & Pricing Performance Dashboard
A2: Premium growth, claim pressure and pricing adequacy view using public insurance data
A3: Sources: GI Council Segment-wise GDPI, IRDAI Annual Report 2024-25, ICICI Lombard Public Disclosures
A5: Selected Premium Apr-25 (₹ Cr) | C5: Selected Premium Apr-26 (₹ Cr) | E5: Selected Segment Growth | G5: Top Insurer | I5: Highest ICR Segment | K5: ICICI Pricing Pressure
A6: =Analysis!D15 -> 29143.19 | C6: =Analysis!D16 -> 31654.17 | E6: =Analysis!D18 -> 0.086160094 | G6: =Analysis!J28 -> The New India Assurance Co Ltd | I6: Motor: 85.51% | K6: Grand Total: 104.98%
A9: Base period premium | C9: Latest period premium | E9: Growth across selected segments | G9: Apr-26 Premium: ₹6,084.98 Cr | I9: IRDAI claim pressure | K9: Analytical load indicator
H29: Claim Pressure & Pricing Caution
H31: Motor ICR | K31: 85.51% — High claim pressure
H34: Health ICR | K34: 85.34% — High claim pressure
H37: ICICI Combined Load | K37: 104.98% — Pricing pressure indicator
H40: Premium growth should not be read as profitability. Claims, ICR, commission load and expense load must be checked before judging pricing adequacy.
A46: Executive Insights & Recommendations
A48: Insight 1 — Premium growth is not profitability | E48: Insight 2 — Motor and Health need claim-pressure monitoring | J48: Insight 3 — ICICI case shows pricing-load pressure
A49: Selected segment premium grew 8.62%, but premium growth only shows business volume. Claims pressure, ICR, commission load and expense load must be checked before judging pricing adequacy. | E49: Motor ICR is 85.51% and Health ICR is 85.34%, placing both in high claim-pressure zones. Growth in these segments should be interpreted with underwriting and claims-control discipline. | J49: ICICI Lombard’s disclosed company-level combined load indicator is 104.98%. This is not the formal combined ratio, but it signals pricing pressure before considering full P&L and investment income.
A55: Sources: GI Council Segment-wise GDPI data, IRDAI Annual Report 2024-25 Table I.14, and ICICI Lombard NL-4 to NL-7 public disclosures. Note: ICICI Combined Load is an analytical indicator, not the formal combined ratio. Selected ICICI segment rows do not add to Grand Total because Grand Total includes additional business lines.

Sheet Analysis
A1: Segment & Insurer Premium Growth Analysis
A3: Source: GI Council Segment-wise GDPI data; values used for Apr-25 vs Apr-26 premium growth analysis
A5: Segment Premium Growth Summary
A7: Segment growth table
A8: Segment | B8: 46137 | D8: 46138 | F8: Change | H8: Growth %
A9: Fire | B9: 6512.37 | D9: 4498.44 | F9: =D9-B9 -> -2013.93 | H9: =F9/B9 -> -0.30924686
A10: Health | B10: 13891.29 | D10: 16893.33 | F10: =D10-B10 -> 3002.04 | H10: =F10/B10 -> 0.21610952
A11: Marine | B11: 870.42 | D11: 1163.17 | F11: =D11-B11 -> 292.75 | H11: =F11/B11 -> 0.33633189
A12: Motor | B12: 7869.11 | D12: 9099.23 | F12: =D12-B12 -> 1230.12 | H12: =F12/B12 -> 0.15632263
A14: Metric | D14: Value
A15: Total Apr-25 Premium | D15: =SUM(B9:B12) -> 29143.19
A16: Total Apr-26 Premium | D16: =SUM(D9:D12) -> 31654.17
A17: Total Change | D17: =D16-D15 -> 2510.98
A18: Total Growth % | D18: =D17/D15 -> 0.086160094
A20: Health is the biggest segment and also grew 21.61%, showing strong premium momentum. Motor_Total also increased by 15.63%. Fire declined by 30.92%, so Fire needs deeper investigation before giving any business conclusion. Marine_Total grew fastest at 33.63%, but its base is much smaller compared to Health and Motor.
A22: In the expanded GI Council data sample, selected segment premium increased by 8.62% from April-25 to April-26. Health is the largest contributor and grew 21.61%, while Motor also grew 15.63%. Marine grew fastest at 33.63%, but from a smaller base. Fire declined sharply by 30.92%, which requires deeper investigation before making a business conclusion.
A24: Insurer Ranking by Apr-26 Premium
A26: Insurers | C26: 46137 | D26: 46138 | E26: Change | F26: Growth % | G26: Rank by April-26 | I26: Top 10 Insurers by April-26 Gross Direct Premium
A27: The New India Assurance Co Ltd | C27: 6026.62 | D27: 6084.98 | E27: =D27-C27 -> 58.36 | F27: =E27/C27 -> 0.0096837033 | G27: =RANK(D27,$D$27:$D$60,0) -> 1 | I27: Rank | J27: Insurer | L27: April-25 Premium | M27: April-26 Premium | N27: Change | O27: Growth %
A28: ICICI Lombard General Insurance Co Ltd | C28: 3592.22 | D28: 3654 | E28: =D28-C28 -> 61.78 | F28: =E28/C28 -> 0.017198279 | G28: =RANK(D28,$D$27:$D$60,0) -> 2 | I28: 1 | J28: The New India Assurance Co Ltd | L28: 6026.62 | M28: 6084.98 | N28: =M28-L28 -> 58.36 | O28: =N28/L28 -> 0.0096837033
A29: Tata AIG General Insurance Co Ltd | C29: 2060.38 | D29: 2845.41 | E29: =D29-C29 -> 785.03 | F29: =E29/C29 -> 0.38101224 | G29: =RANK(D29,$D$27:$D$60,0) -> 3 | I29: 2 | J29: ICICI Lombard General Insurance Co Ltd | L29: 3592.22 | M29: 3654 | N29: =M29-L29 -> 61.78 | O29: =N29/L29 -> 0.017198279
A30: The Oriental Insurance Co Ltd | C30: 2629.9 | D30: 2670.24 | E30: =D30-C30 -> 40.34 | F30: =E30/C30 -> 0.015338986 | G30: =RANK(D30,$D$27:$D$60,0) -> 4 | I30: 3 | J30: Tata AIG General Insurance Co Ltd | L30: 2060.38 | M30: 2845.41 | N30: =M30-L30 -> 785.03 | O30: =N30/L30 -> 0.38101224
A31: Bajaj General Insurance Limited | C31: 2402.82 | D31: 2665.55 | E31: =D31-C31 -> 262.73 | F31: =E31/C31 -> 0.10934236 | G31: =RANK(D31,$D$27:$D$60,0) -> 5 | I31: 4 | J31: The Oriental Insurance Co Ltd | L31: 2629.9 | M31: 2670.24 | N31: =M31-L31 -> 40.34 | O31: =N31/L31 -> 0.015338986
A32: United India Insurance Co Ltd | C32: 2093.11 | D32: 2117.24 | E32: =D32-C32 -> 24.13 | F32: =E32/C32 -> 0.0115283 | G32: =RANK(D32,$D$27:$D$60,0) -> 6 | I32: 5 | J32: Bajaj General Insurance Limited | L32: 2402.82 | M32: 2665.55 | N32: =M32-L32 -> 262.73 | O32: =N32/L32 -> 0.10934236
A33: HDFC Ergo General Insurance Co Ltd | C33: 1619.92 | D33: 1743.28 | E33: =D33-C33 -> 123.36 | F33: =E33/C33 -> 0.076151909 | G33: =RANK(D33,$D$27:$D$60,0) -> 7 | I33: 6 | J33: United India Insurance Co Ltd | L33: 2093.11 | M33: 2117.24 | N33: =M33-L33 -> 24.13 | O33: =N33/L33 -> 0.0115283
A34: National Insurance Co Ltd | C34: 1528.72 | D34: 1605.18 | E34: =D34-C34 -> 76.46 | F34: =E34/C34 -> 0.050015699 | G34: =RANK(D34,$D$27:$D$60,0) -> 8 | I34: 7 | J34: HDFC Ergo General Insurance Co Ltd | L34: 1619.92 | M34: 1743.28 | N34: =M34-L34 -> 123.36 | O34: =N34/L34 -> 0.076151909
A35: IndusInd General Insurance Company Limited | C35: 1479.26 | D35: 1563.91 | E35: =D35-C35 -> 84.65 | F35: =E35/C35 -> 0.057224558 | G35: =RANK(D35,$D$27:$D$60,0) -> 9 | I35: 8 | J35: National Insurance Co Ltd | L35: 1528.72 | M35: 1605.18 | N35: =M35-L35 -> 76.46 | O35: =N35/L35 -> 0.050015699
A36: SBI General Insurance Co Ltd | C36: 1290.55 | D36: 1299.53 | E36: =D36-C36 -> 8.98 | F36: =E36/C36 -> 0.0069582736 | G36: =RANK(D36,$D$27:$D$60,0) -> 10 | I36: 9 | J36: IndusInd General Insurance Company Limited | L36: 1479.26 | M36: 1563.91 | N36: =M36-L36 -> 84.65 | O36: =N36/L36 -> 0.057224558
A37: Star Health & Allied Insurance Co Ltd | C37: 1060.16 | D37: 1264.54 | E37: =D37-C37 -> 204.38 | F37: =E37/C37 -> 0.19278222 | G37: =RANK(D37,$D$27:$D$60,0) -> 11 | I37: 10 | J37: SBI General Insurance Co Ltd | L37: 1290.55 | M37: 1299.53 | N37: =M37-L37 -> 8.98 | O37: =N37/L37 -> 0.0069582736
A38: Care Health Insurance Ltd | C38: 726.19 | D38: 1008.78 | E38: =D38-C38 -> 282.59 | F38: =E38/C38 -> 0.38914058 | G38: =RANK(D38,$D$27:$D$60,0) -> 12 | I38: Insight: New India Assurance leads by April-26 premium volume, followed by ICICI Lombard and Tata AIG. Tata AIG shows the strongest growth among the top 10 insurers at 38.10%, while most public-sector insurers show stable but slower growth. Premium volume indicates market size, not profitability; claims ratio, expense ratio and combined ratio must be checked separately.
A39: Go Digit General Insurance Ltd | C39: 1000.65 | D39: 967.55 | E39: =D39-C39 -> -33.1 | F39: =E39/C39 -> -0.033078499 | G39: =RANK(D39,$D$27:$D$60,0) -> 13
A40: IFFCO-Tokio General Insurance Co Ltd | C40: 783.53 | D40: 876.75 | E40: =D40-C40 -> 93.22 | F40: =E40/C40 -> 0.11897439 | G40: =RANK(D40,$D$27:$D$60,0) -> 14
A41: Cholamandalam MS General Insurance Co Ltd | C41: 708.58 | D41: 745.38 | E41: =D41-C41 -> 36.8 | F41: =E41/C41 -> 0.051934856 | G41: =RANK(D41,$D$27:$D$60,0) -> 15
A42: Aditya Birla Health Insurance Co Ltd | C42: 438.37 | D42: 731.98 | E42: =D42-C42 -> 293.61 | F42: =E42/C42 -> 0.66977667 | G42: =RANK(D42,$D$27:$D$60,0) -> 16
A43: Universal Sompo General Insurance Co Ltd | C43: 472.83 | D43: 695.55 | E43: =D43-C43 -> 222.72 | F43: =E43/C43 -> 0.4710361 | G43: =RANK(D43,$D$27:$D$60,0) -> 17
A44: Niva bupa health insurance company limited | C44: 483.07 | D44: 629.26 | E44: =D44-C44 -> 146.19 | F44: =E44/C44 -> 0.30262695 | G44: =RANK(D44,$D$27:$D$60,0) -> 18 | P44: Chart Source: Top 10 Insurers
A45: Royal Sundaram General Insurance Co Ltd | C45: 520.28 | D45: 576.48 | E45: =D45-C45 -> 56.2 | F45: =E45/C45 -> 0.10801876 | G45: =RANK(D45,$D$27:$D$60,0) -> 19 | P45: Insurer | Q45: April-26 Premium
A46: Generali Central Insurance Company Limited | C46: 641.05 | D46: 515.23 | E46: =D46-C46 -> -125.82 | F46: =E46/C46 -> -0.19627174 | G46: =RANK(D46,$D$27:$D$60,0) -> 20 | P46: SBI General | Q46: 1299.53
A47: Magma General Insurance Limited | C47: 380.05 | D47: 376.9 | E47: =D47-C47 -> -3.15 | F47: =E47/C47 -> -0.0082883831 | G47: =RANK(D47,$D$27:$D$60,0) -> 21 | P47: IndusInd | Q47: 1563.91
A48: Shriram General Insurance Co Ltd | C48: 290.39 | D48: 361.54 | E48: =D48-C48 -> 71.15 | F48: =E48/C48 -> 0.24501532 | G48: =RANK(D48,$D$27:$D$60,0) -> 22 | P48: National | Q48: 1605.18
...

Sheet IRDAI_ICR_Data
A1: Segment-wise Incurred Claims Ratio Analysis
A2: Claim pressure view based on IRDAI Annual Report 2024-25
A4: Purpose | B4: Connect premium growth with incurred claims pressure
A5: Source | B5: IRDAI Annual Report 2024-25
A6: Source Table | B6: Table I.14: Segment-wise Incurred Claims Ratio
A7: Metric | B7: ICR = Net incurred claims / Net earned premium
A8: Project Logic | B8: Premium growth shows volume; ICR shows claim pressure
A10: Segment | B10: FY2023_24_ICR | C10: FY2024_25_ICR | D10: Change_pp | E10: Direction | F10: Pressure_Band | G10: Business_Interpretation | H10: Source | I10: Dashboard_Use
A11: =Raw_IRDAI!A6 -> Fire | B11: =Raw_IRDAI!F6 -> 78.33 | C11: =Raw_IRDAI!K6 -> 72.93 | D11: =(C11-B11) -> -5.4 | E11: =IF(D11>1,"Worsening",IF(D11<-1,"Improving","Stable")) -> Improving | F11: =IF(C11>=85,"High",IF(C11>=75,"Medium","Controlled")) -> Controlled | G11: Fire claim pressure improved. Even though Fire premium declined earlier, lower ICR means we should not call the segment weak without checking pricing and portfolio mix. | H11: IRDAI Annual Report 2024-25 Table I.14 | I11: Example of lower premium but improved claim pressure
A12: =Raw_IRDAI!A7 -> Marine | B12: =Raw_IRDAI!F7 -> 72.39 | C12: =Raw_IRDAI!K7 -> 73.63 | D12: =(C12-B12) -> 1.24 | E12: =IF(D12>1,"Worsening",IF(D12<-1,"Improving","Stable")) -> Worsening | F12: =IF(C12>=85,"High",IF(C12>=75,"Medium","Controlled")) -> Controlled | G12: Marine ICR increased slightly, but remains controlled. Marine premium growth is strong, but from a smaller base. | H12: IRDAI Annual Report 2024-25 Table I.14 | I12: Controlled growth segment
A13: =Raw_IRDAI!A8 -> Motor | B13: =Raw_IRDAI!F8 -> 81.98 | C13: =Raw_IRDAI!K8 -> 85.51 | D13: =(C13-B13) -> 3.53 | E13: =IF(D13>1,"Worsening",IF(D13<-1,"Improving","Stable")) -> Worsening | F13: =IF(C13>=85,"High",IF(C13>=75,"Medium","Controlled")) -> High | G13: Motor is the main warning signal. Premium growth is positive, but ICR increased and moved into the high-pressure band. | H13: IRDAI Annual Report 2024-25 Table I.14 | I13: Key claim-pressure warning
A14: =Raw_IRDAI!A9 -> Health | B14: =Raw_IRDAI!F9 -> 86.35 | C14: =Raw_IRDAI!K9 -> 85.34 | D14: =(C14-B14) -> -1.01 | E14: =IF(D14>1,"Worsening",IF(D14<-1,"Improving","Stable")) -> Improving | F14: =IF(C14>=85,"High",IF(C14>=75,"Medium","Controlled")) -> High | G14: Health remains high-pressure. ICR improved slightly, but claims still consume a large share of premium. | H14: IRDAI Annual Report 2024-25 Table I.14 | I14: Large segment with structural claim pressure
A15: =Raw_IRDAI!A10 -> Others | B15: =Raw_IRDAI!F10 -> 72.78 | C15: =Raw_IRDAI!K10 -> 68.62 | D15: =(C15-B15) -> -4.16 | E15: =IF(D15>1,"Worsening",IF(D15<-1,"Improving","Stable")) -> Improving | F15: =IF(C15>=85,"High",IF(C15>=75,"Medium","Controlled")) -> Controlled | G15: Others improved and is currently more controlled than Motor and Health. | H15: IRDAI Annual Report 2024-25 Table I.14 | I15: Low-pressure comparison segment
A16: Industry Total | B16: =Raw_IRDAI!F11 -> 82.52 | C16: =Raw_IRDAI!K11 -> 82.88 | D16: =(C16-B16) -> 0.36 | E16: =IF(D16>1,"Worsening",IF(D16<-1,"Improving","Stable")) -> Stable | F16: =IF(C16>=85,"High",IF(C16>=75,"Medium","Controlled")) -> Medium | G16: Industry ICR is broadly stable but still elevated above 80%, so claim pressure remains important even when premium grows. | H16: IRDAI Annual Report 2024-25 Table I.14 | I16: Industry benchmark
A19: Premium Growth vs Claim Pressure
A21: Segment | B21: Apr_25_Premium | C21: Apr_26_Premium | D21: Premium_Growth | E21: FY2024_25_ICR | F21: Claim_Pressure | G21: Combined_View | H21: Dashboard_Message | I21: Analyst_Note
A22: Fire | B22: =Analysis!B9 -> 6512.37 | C22: =Analysis!D9 -> 4498.44 | D22: =Analysis!H9 -> -0.30924686 | E22: =C11 -> 72.93 | F22: =F11 -> Controlled | G22: Fire premium declined, but ICR improved. This suggests the segment should not be judged only by premium movement. | H22: Decline with improved claim pressure | I22: Check portfolio mix and pricing before calling Fire weak.
A23: Health | B23: =Analysis!B10 -> 13891.29 | C23: =Analysis!D10 -> 16893.33 | D23: =Analysis!H10 -> 0.21610952 | E23: =C14 -> 85.34 | F23: =F14 -> High | G23: Health is the largest selected segment and grew strongly, but ICR remains high. | H23: Large growth with high claim pressure | I23: Strong growth must be checked against medical inflation and claim cost.
A24: Marine | B24: =Analysis!B11 -> 870.42 | C24: =Analysis!D11 -> 1163.17 | D24: =Analysis!H11 -> 0.33633189 | E24: =C12 -> 73.63 | F24: =F12 -> Controlled | G24: Marine grew fastest, and ICR remains controlled, but the base is much smaller than Health and Motor. | H24: Fast growth from small base | I24: Do not overstate Marine because premium base is small.
A25: Motor | B25: =Analysis!B12 -> 7869.11 | C25: =Analysis!D12 -> 9099.23 | D25: =Analysis!H12 -> 0.15632263 | E25: =C13 -> 85.51 | F25: =F13 -> High | G25: Motor premium grew, but ICR moved into the high-pressure band. This is the clearest pricing-pressure warning. | H25: Growth with high claim-pressure warning | I25: Motor needs pricing, underwriting and claims-control attention.
A28: Key Claim-Pressure Insights
A30: Insight 1 — Growth is not profitability | D30: Insight 2 — Motor is the key warning | G30: Insight 3 — Health is large but pressured
A31: Selected segment premium grew by 8.62%, but premium growth only shows business volume. To judge pricing adequacy, we must check whether claims are consuming too much of earned premium. | D31: Motor premium grew 15.63%, but FY2024-25 Motor ICR is 85.51%. This means Motor growth must be read with caution because claim pressure is high and worsening. | G31: Health is the largest selected segment and grew 21.61%, but FY2024-25 Health ICR remains high at 85.34%. This supports a pricing adequacy and claims-management story, not only a growth story.

Sheet ICICI_Company_Case
A1: ICICI Lombard Company-Level Pricing Case
A3: Source: ICICI Lombard NL-4, NL-5, NL-6 and NL-7 Periodic Disclosures; values in ₹ lakhs
A5: Segment | B5: Net Earned Premium | C5: Net Incurred Claims | D5: Claim Ratio | E5: Net Commission | F5: Commission Load | G5: Operating Expenses | H5: Expense Load | I5: Combined Load | J5: Pricing Pressure Band | K5: Business Interpretation
A6: Fire | B6: =Raw_ICICI_NL4!E6 -> 69024 | C6: =Raw_ICICI_NL5!C6 -> 36288 | D6: =C6/B6 -> 0.52573018 | E6: =Raw_ICICI_NL6!E6 -> -21496 | F6: =E6/B6 -> -0.31142791 | G6: =Raw_ICICI_NL7!C6 -> 11744 | H6: =G6/B6 -> 0.17014372 | I6: =D6+F6+H6 -> 0.38444599 | J6: =IF(I6>=1,"High",IF(I6>=0.85,"Watch","Controlled")) -> Controlled | K6: Fire has improved claim load but should be interpreted with reinsurance and portfolio mix because net commission is negative.
A7: Total Marine | B7: =Raw_ICICI_NL4!E7 -> 62423 | C7: =Raw_ICICI_NL5!C7 -> 56718 | D7: =C7/B7 -> 0.9086074 | E7: =Raw_ICICI_NL6!E7 -> 9394 | F7: =E7/B7 -> 0.1504894 | G7: =Raw_ICICI_NL7!C7 -> 8911 | H7: =G7/B7 -> 0.14275187 | I7: =D7+F7+H7 -> 1.2018487 | J7: =IF(I7>=1,"High",IF(I7>=0.85,"Watch","Controlled")) -> High | K7: Marine has moderate claim pressure and should be treated as smaller-base business, not the main company driver.
A8: Total Motor | B8: =Raw_ICICI_NL4!E8 -> 1102482 | C8: =Raw_ICICI_NL5!C8 -> 730697 | D8: =C8/B8 -> 0.66277454 | E8: =Raw_ICICI_NL6!E8 -> 352153 | F8: =E8/B8 -> 0.31941837 | G8: =Raw_ICICI_NL7!C8 -> 105427 | H8: =G8/B8 -> 0.095626958 | I8: =D8+F8+H8 -> 1.0778199 | J8: =IF(I8>=1,"High",IF(I8>=0.85,"Watch","Controlled")) -> High | K8: Motor is the biggest pricing-pressure warning because claims plus acquisition/expense load consume a large share of earned premium.
A9: Total Health | B9: =Raw_ICICI_NL4!E9 -> 841201 | C9: =Raw_ICICI_NL5!C9 -> 659370 | D9: =C9/B9 -> 0.78384358 | E9: =Raw_ICICI_NL6!E9 -> 101495 | F9: =E9/B9 -> 0.12065487 | G9: =Raw_ICICI_NL7!C9 -> 145745 | H9: =G9/B9 -> 0.17325823 | I9: =D9+F9+H9 -> 1.0777567 | J9: =IF(I9>=1,"High",IF(I9>=0.85,"Watch","Controlled")) -> High | K9: Health remains important because premium scale is large and claim/expense pressure needs monitoring.
A10: Grand Total | B10: =Raw_ICICI_NL4!E10 -> 2226357 | C10: =Raw_ICICI_NL5!C10 -> 1582847 | D10: =C10/B10 -> 0.71095831 | E10: =Raw_ICICI_NL6!E10 -> 448419 | F10: =E10/B10 -> 0.20141379 | G10: =Raw_ICICI_NL7!C10 -> 305855 | H10: =G10/B10 -> 0.13737914 | I10: =D10+F10+H10 -> 1.0497512 | J10: =IF(I10>=1,"High",IF(I10>=0.85,"Watch","Controlled")) -> High | K10: Company-level disclosed total gives the overall pricing pressure view, not the sum of selected rows only.
A12: Note: Combined Load = Claim Ratio + Commission Load + Expense Load. It is an analytical pricing-pressure indicator, not the formal combined ratio. Fire has lower combined load partly due to negative net commission. Grand Total is the disclosed company-level figure, not the sum of only selected rows.
A15: ICICI Lombard Pricing Case Insights
A17: Insight 1 — Marine shows highest pressure | D17: Insight 2 — Motor remains the key business warning | H17: Insight 3 — Company-level pressure is above 100%
A18: Total Marine has the highest combined load at 120.18%. Even though Marine is a smaller-base segment, claims plus commission and expenses exceed earned premium, so it should be treated as a high-pressure segment in this case study. | D18: Total Motor has a combined load of 107.78%. Motor is a large business line, so even moderate-looking claim ratio becomes important when commission and operating expense load are added. This supports a pricing and claims-control warning. | H18: Grand Total combined load is 104.98%, meaning claims, net commission and operating expenses together exceed net earned premium. This does not equal final profitability, but it shows pricing adequacy pressure before investment income and other items.

Sheet Pivot_Auto_Segment_Analysis
A1: Sum of Premium_Amount | B1: Column labels
A2: Row labels | B2: April-25 | C2: April-26 | D2: Grand total
A3: Fire | B3: 6512.37 | C3: 4498.44 | D3: 11010.81
A4: Health | B4: 13891.29 | C4: 16893.33 | D4: 30784.62
A5: Marine_Total | B5: 870.42 | C5: 1163.17 | D5: 2033.59
A6: Motor_Total | B6: 7869.11 | C6: 9099.23 | D6: 16968.34
A7: Grand total | B7: 29143.19 | C7: 31654.17 | D7: 60797.36

Sheet Pivot_Insurer_Analysis
A1: Segment | B1: Grand_Total
A3: Sum of Premium_Amount | B3: Column labels
A4: Row labels | B4: April-25 | C4: April-26 | D4: Grand total
A5: Acko General Insurance Ltd | B5: 177.43 | C5: 286.54 | D5: 463.97
A6: Aditya Birla Health Insurance Co Ltd | B6: 438.37 | C6: 731.98 | D6: 1170.35
A7: Agriculture Insurance Co Of India Ltd | B7: 5.78 | C7: 16.48 | D7: 22.26
A8: Bajaj General Insurance Limited | B8: 2402.82 | C8: 2665.55 | D8: 5068.37
A9: Care Health Insurance Ltd | B9: 726.19 | C9: 1008.78 | D9: 1734.97
A10: Cholamandalam MS General Insurance Co Ltd | B10: 708.58 | C10: 745.38 | D10: 1453.96
A11: ECGC Ltd | B11: 87.66 | C11: 106.47 | D11: 194.13
A12: Galaxy Health Insurance Company Ltd | B12: 3.38 | C12: 13.09 | D12: 16.47
A13: Generali Central Insurance Company Limited | B13: 641.05 | C13: 515.23 | D13: 1156.28
A14: Go Digit General Insurance Ltd | B14: 1000.65 | C14: 967.55 | D14: 1968.2
A15: HDFC Ergo General Insurance Co Ltd | B15: 1619.92 | C15: 1743.28 | D15: 3363.2
A16: ICICI Lombard General Insurance Co Ltd | B16: 3592.22 | C16: 3654 | D16: 7246.22
... A39: Grand total | B39: 33593.5 | C39: 36417.68 | D39: 70011.18

Sheet Cleaned_Auto
A1: Insurer | B1: Period | C1: Segment | D1: Premium_Amount | E1: Source
A2: =INDEX(Raw_GI_Council!$B$2:$B$100,ROUNDUP(ROW(A1)/5,0)) -> Acko General Insurance Ltd | B2: =INDEX(Raw_GI_Council!$C$2:$C$100,ROUNDUP(ROW(A1)/5,0)) -> April-26 | C2: =INDEX(Raw_GI_Council!$D$1:$H$1,1,MOD(ROW(A1)-1,5)+1) -> Fire | D2: =IF(INDEX(Raw_GI_Council!$D$2:$H$100,ROUNDUP(ROW(A1)/5,0),MOD(ROW(A1)-1,5)+1)="-",0,INDEX(Raw_GI_Council!$D$2:$H$100,ROUNDUP(ROW(A1)/5,0),MOD(ROW(A1)-1,5)+1)) -> 0.1 | E2: ="GI Council" -> GI Council
A3: =INDEX(Raw_GI_Council!$B$2:$B$100,ROUNDUP(ROW(A2)/5,0)) -> Acko General Insurance Ltd | B3: =INDEX(Raw_GI_Council!$C$2:$C$100,ROUNDUP(ROW(A2)/5,0)) -> April-26 | C3: =INDEX(Raw_GI_Council!$D$1:$H$1,1,MOD(ROW(A2)-1,5)+1) -> Marine_Total | D3: =IF(INDEX(Raw_GI_Council!$D$2:$H$100,ROUNDUP(ROW(A2)/5,0),MOD(ROW(A2)-1,5)+1)="-",0,INDEX(Raw_GI_Council!$D$2:$H$100,ROUNDUP(ROW(A2)/5,0),MOD(ROW(A2)-1,5)+1)) -> 0 | E3: ="GI Council" -> GI Council
A4: =INDEX(Raw_GI_Council!$B$2:$B$100,ROUNDUP(ROW(A3)/5,0)) -> Acko General Insurance Ltd | B4: =INDEX(Raw_GI_Council!$C$2:$C$100,ROUNDUP(ROW(A3)/5,0)) -> April-26 | C4: =INDEX(Raw_GI_Council!$D$1:$H$1,1,MOD(ROW(A3)-1,5)+1) -> Motor_Total | D4: =IF(INDEX(Raw_GI_Council!$D$2:$H$100,ROUNDUP(ROW(A3)/5,0),MOD(ROW(A3)-1,5)+1)="-",0,INDEX(Raw_GI_Council!$D$2:$H$100,ROUNDUP(ROW(A3)/5,0),MOD(ROW(A3)-1,5)+1)) -> 93.25 | E4: ="GI Council" -> GI Council
A5: =INDEX(Raw_GI_Council!$B$2:$B$100,ROUNDUP(ROW(A4)/5,0)) -> Acko General Insurance Ltd | B5: =INDEX(Raw_GI_Council!$C$2:$C$100,ROUNDUP(ROW(A4)/5,0)) -> April-26 | C5: =INDEX(Raw_GI_Council!$D$1:$H$1,1,MOD(ROW(A4)-1,5)+1) -> Health | D5: =IF(INDEX(Raw_GI_Council!$D$2:$H$100,ROUNDUP(ROW(A4)/5,0),MOD(ROW(A4)-1,5)+1)="-",0,INDEX(Raw_GI_Council!$D$2:$H$100,ROUNDUP(ROW(A4)/5,0),MOD(ROW(A4)-1,5)+1)) -> 172.42 | E5: ="GI Council" -> GI Council
A6: =INDEX(Raw_GI_Council!$B$2:$B$100,ROUNDUP(ROW(A5)/5,0)) -> Acko General Insurance Ltd | B6: =INDEX(Raw_GI_Council!$C$2:$C$100,ROUNDUP(ROW(A5)/5,0)) -> April-26 | C6: =INDEX(Raw_GI_Council!$D$1:$H$1,1,MOD(ROW(A5)-1,5)+1) -> Grand_Total | D6: =IF(INDEX(Raw_GI_Council!$D$2:$H$100,ROUNDUP(ROW(A5)/5,0),MOD(ROW(A5)-1,5)+1)="-",0,INDEX(Raw_GI_Council!$D$2:$H$100,ROUNDUP(ROW(A5)/5,0),MOD(ROW(A5)-1,5)+1)) -> 286.54 | E6: ="GI Council" -> GI Council
A7: =INDEX(Raw_GI_Council!$B$2:$B$100,ROUNDUP(ROW(A6)/5,0)) -> Acko General Insurance Ltd | B7: =INDEX(Raw_GI_Council!$C$2:$C$100,ROUNDUP(ROW(A6)/5,0)) -> April-25 | C7: =INDEX(Raw_GI_Council!$D$1:$H$1,1,MOD(ROW(A6)-1,5)+1) -> Fire | D7: =IF(INDEX(Raw_GI_Council!$D$2:$H$100,ROUNDUP(ROW(A6)/5,0),MOD(ROW(A6)-1,5)+1)="-",0,INDEX(Raw_GI_Council!$D$2:$H$100,ROUNDUP(ROW(A6)/5,0),MOD(ROW(A6)-1,5)+1)) -> 0 | E7: ="GI Council" -> GI Council
A8: =INDEX(Raw_GI_Council!$B$2:$B$100,ROUNDUP(ROW(A7)/5,0)) -> Acko General Insurance Ltd | B8: =INDEX(Raw_GI_Council!$C$2:$C$100,ROUNDUP(ROW(A7)/5,0)) -> April-25 | C8: =INDEX(Raw_GI_Council!$D$1:$H$1,1,MOD(ROW(A7)-1,5)+1) -> Marine_Total | D8: =IF(INDEX(Raw_GI_Council!$D$2:$H$100,ROUNDUP(ROW(A7)/5,0),MOD(ROW(A7)-1,5)+1)="-",0,INDEX(Raw_GI_Council!$D$2:$H$100,ROUNDUP(ROW(A7)/5,0),MOD(ROW(A7)-1,5)+1)) -> 0 | E8: ="GI Council" -> GI Council
A9: =INDEX(Raw_GI_Council!$B$2:$B$100,ROUNDUP(ROW(A8)/5,0)) -> Acko General Insurance Ltd | B9: =INDEX(Raw_GI_Council!$C$2:$C$100,ROUNDUP(ROW(A8)/5,0)) -> April-25 | C9: =INDEX(Raw_GI_Council!$D$1:$H$1,1,MOD(ROW(A8)-1,5)+1) -> Motor_Total | D9: =IF(INDEX(Raw_GI_Council!$D$2:$H$100,ROUNDUP(ROW(A8)/5,0),MOD(ROW(A8)-1,5)+1)="-",0,INDEX(Raw_GI_Council!$D$2:$H$100,ROUNDUP(ROW(A8)/5,0),MOD(ROW(A8)-1,5)+1)) -> 76.86 | E9: ="GI Council" -> GI Council
A10: =INDEX(Raw_GI_Council!$B$2:$B$100,ROUNDUP(ROW(A9)/5,0)) -> Acko General Insurance Ltd | B10: =INDEX(Raw_GI_Council!$C$2:$C$100,ROUNDUP(ROW(A9)/5,0)) -> April-25 | C10: =INDEX(Raw_GI_Council!$D$1:$H$1,1,MOD(ROW(A9)-1,5)+1) -> Health | D10: =IF(INDEX(Raw_GI_Council!$D$2:$H$100,ROUNDUP(ROW(A9)/5,0),MOD(ROW(A9)-1,5)+1)="-",0,INDEX(Raw_GI_Council!$D$2:$H$100,ROUNDUP(ROW(A9)/5,0),MOD(ROW(A9)-1,5)+1)) -> 89.99 | E10: ="GI Council" -> GI Council
A11: =INDEX(Raw_GI_Council!$B$2:$B$100,ROUNDUP(ROW(A10)/5,0)) -> Acko General Insurance Ltd | B11: =INDEX(Raw_GI_Council!$C$2:$C$100,ROUNDUP(ROW(A10)/5,0)) -> April-25 | C11: =INDEX(Raw_GI_Council!$D$1:$H$1,1,MOD(ROW(A10)-1,5)+1) -> Grand_Total | D11: =IF(INDEX(Raw_GI_Council!$D$2:$H$100,ROUNDUP(ROW(A10)/5,0),MOD(ROW(A10)-1,5)+1)="-",0,INDEX(Raw_GI_Council!$D$2:$H$100,ROUNDUP(ROW(A10)/5,0),MOD(ROW(A10)-1,5)+1)) -> 177.43 | E11: ="GI Council" -> GI Council
A12: =INDEX(Raw_GI_Council!$B$2:$B$100,ROUNDUP(ROW(A11)/5,0)) -> Bajaj General Insurance Limited | B12: =INDEX(Raw_GI_Council!$C$2:$C$100,ROUNDUP(ROW(A11)/5,0)) -> April-26 | C12: =INDEX(Raw_GI_Council!$D$1:$H$1,1,MOD(ROW(A11)-1,5)+1) -> Fire | D12: =IF(INDEX(Raw_GI_Council!$D$2:$H$100,ROUNDUP(ROW(A11)/5,0),MOD(ROW(A11)-1,5)+1)="-",0,INDEX(Raw_GI_Council!$D$2:$H$100,ROUNDUP(ROW(A11)/5,0),MOD(ROW(A11)-1,5)+1)) -> 578.54 | E12: ="GI Council" -> GI Council
A13: =INDEX(Raw_GI_Council!$B$2:$B$100,ROUNDUP(ROW(A12)/5,0)) -> Bajaj General Insurance Limited | B13: =INDEX(Raw_GI_Council!$C$2:$C$100,ROUNDUP(ROW(A12)/5,0)) -> April-26 | C13: =INDEX(Raw_GI_Council!$D$1:$H$1,1,MOD(ROW(A12)-1,5)+1) -> Marine_Total | D13: =IF(INDEX(Raw_GI_Council!$D$2:$H$100,ROUNDUP(ROW(A12)/5,0),MOD(ROW(A12)-1,5)+1)="-",0,INDEX(Raw_GI_Council!$D$2:$H$100,ROUNDUP(ROW(A12)/5,0),MOD(ROW(A12)-1,5)+1)) -> 111.47 | E13: ="GI Council" -> GI Council
... A341: =INDEX(Raw_GI_Council!$B$2:$B$100,ROUNDUP(ROW(A340)/5,0)) -> ECGC Ltd | B341: =INDEX(Raw_GI_Council!$C$2:$C$100,ROUNDUP(ROW(A340)/5,0)) -> April-25 | C341: =INDEX(Raw_GI_Council!$D$1:$H$1,1,MOD(ROW(A340)-1,5)+1) -> Grand_Total | D341: =IF(INDEX(Raw_GI_Council!$D$2:$H$100,ROUNDUP(ROW(A340)/5,0),MOD(ROW(A340)-1,5)+1)="-",0,INDEX(Raw_GI_Council!$D$2:$H$100,ROUNDUP(ROW(A340)/5,0),MOD(ROW(A340)-1,5)+1)) -> 87.66 | E341: ="GI Council" -> GI Council

Sheet Raw_GI_Council
A1: Insurer_Raw | B1: Insurer | C1: Period | D1: Fire | E1: Marine_Total | F1: Motor_Total | G1: Health | H1: Grand_Total
A2: Acko General Insurance Ltd | B2: =IF(A2="Previous Year",B1,A2) -> Acko General Insurance Ltd | C2: =IF(A2="Previous Year","April-25","April-26") -> April-26 | D2: 0.1 | E2: 0 | F2: 93.25 | G2: 172.42 | H2: 286.54
A3: Previous Year | B3: =IF(A3="Previous Year",B2,A3) -> Acko General Insurance Ltd | C3: =IF(A3="Previous Year","April-25","April-26") -> April-25 | D3: 0 | E3: 0 | F3: 76.86 | G3: 89.99 | H3: 177.43
A4: Bajaj General Insurance Limited | B4: =IF(A4="Previous Year",B3,A4) -> Bajaj General Insurance Limited | C4: =IF(A4="Previous Year","April-25","April-26") -> April-26 | D4: 578.54 | E4: 111.47 | F4: 615.23 | G4: 942.86 | H4: 2665.55
A5: Previous Year | B5: =IF(A5="Previous Year",B4,A5) -> Bajaj General Insurance Limited | C5: =IF(A5="Previous Year","April-25","April-26") -> April-25 | D5: 778.64 | E5: 72.96 | F5: 546.71 | G5: 645.91 | H5: 2402.82
A6: Cholamandalam MS General Insurance Co Ltd | B6: =IF(A6="Previous Year",B5,A6) -> Cholamandalam MS General Insurance Co Ltd | C6: =IF(A6="Previous Year","April-25","April-26") -> April-26 | D6: 98.83 | E6: 73.78 | F6: 451.49 | G6: 85.76 | H6: 745.38
A7: Previous Year | B7: =IF(A7="Previous Year",B6,A7) -> Cholamandalam MS General Insurance Co Ltd | C7: =IF(A7="Previous Year","April-25","April-26") -> April-25 | D7: 123.31 | E7: 30.75 | F7: 404.49 | G7: 122.64 | H7: 708.58
A8: Generali Central Insurance Company Limited | B8: =IF(A8="Previous Year",B7,A8) -> Generali Central Insurance Company Limited | C8: =IF(A8="Previous Year","April-25","April-26") -> April-26 | D8: 82.89 | E8: 21.84 | F8: 174.38 | G8: 180.8 | H8: 515.23
A9: Previous Year | B9: =IF(A9="Previous Year",B8,A9) -> Generali Central Insurance Company Limited | C9: =IF(A9="Previous Year","April-25","April-26") -> April-25 | D9: 158.56 | E9: 20.31 | F9: 151.8 | G9: 263.49 | H9: 641.05
A10: Go Digit General Insurance Ltd | B10: =IF(A10="Previous Year",B9,A10) -> Go Digit General Insurance Ltd | C10: =IF(A10="Previous Year","April-25","April-26") -> April-26 | D10: 109.47 | E10: 27.3 | F10: 517.31 | G10: 204.3 | H10: 967.55
A11: Previous Year | B11: =IF(A11="Previous Year",B10,A11) -> Go Digit General Insurance Ltd | C11: =IF(A11="Previous Year","April-25","April-26") -> April-25 | D11: 213.49 | E11: 21.91 | F11: 496.64 | G11: 184.75 | H11: 1000.65
A12: HDFC Ergo General Insurance Co Ltd | B12: =IF(A12="Previous Year",B11,A12) -> HDFC Ergo General Insurance Co Ltd | C12: =IF(A12="Previous Year","April-25","April-26") -> April-26 | D12: 337.14 | E12: 49.67 | F12: 284.94 | G12: 779.6 | H12: 1743.28
A13: Previous Year | B13: =IF(A13="Previous Year",B12,A13) -> HDFC Ergo General Insurance Co Ltd | C13: =IF(A13="Previous Year","April-25","April-26") -> April-25 | D13: 524.92 | E13: 33.25 | F13: 193.08 | G13: 612.1 | H13: 1619.92
... A51: Previous Year | B51: =IF(A51="Previous Year",B50,A51) -> Zurich Kotak Mahindra General Insurance Co Ltd | C51: =IF(A51="Previous Year","April-25","April-26") -> April-25 | D51: 7.02 | E51: 2.16 | F51: 82.1 | G51: 130.8 | H51: 233.66
A52: Niva bupa health insurance company limited | B52: =IF(A52="Previous Year",#REF!,A52) -> Niva bupa health insurance company limited | C52: =IF(A52="Previous Year","April-25","April-26") -> April-26 | D52: 0 | E52: 0 | F52: 0 | G52: 620.45 | H52: 629.26
A53: Previous Year | B53: =IF(A53="Previous Year",B52,A53) -> Niva bupa health insurance company limited | C53: =IF(A53="Previous Year","April-25","April-26") -> April-25 | D53: 0 | E53: 0 | F53: 0 | G53: 475.51 | H53: 483.07
A54: Aditya Birla Health Insurance Co Ltd | B54: =IF(A54="Previous Year",B53,A54) -> Aditya Birla Health Insurance Co Ltd | C54: =IF(A54="Previous Year","April-25","April-26") -> April-26 | D54: 0 | E54: 0 | F54: 0 | G54: 661.67 | H54: 731.98
A55: Previous Year | B55: =IF(A55="Previous Year",B54,A55) -> Aditya Birla Health Insurance Co Ltd | C55: =IF(A55="Previous Year","April-25","April-26") -> April-25 | D55: 0 | E55: 0 | F55: 0 | G55: 430.13 | H55: 438.37
A56: Care Health Insurance Ltd | B56: =IF(A56="Previous Year",B55,A56) -> Care Health Insurance Ltd | C56: =IF(A56="Previous Year","April-25","April-26") -> April-26 | D56: 0 | E56: 0 | F56: 0 | G56: 986.51 | H56: 1008.78
A57: Previous Year | B57: =IF(A57="Previous Year",B56,A57) -> Care Health Insurance Ltd | C57: =IF(A57="Previous Year","April-25","April-26") -> April-25 | D57: 0 | E57: 0 | F57: 0 | G57: 710.6 | H57: 726.19
A58: Galaxy Health Insurance Company Ltd | B58: =IF(A58="Previous Year",B57,A58) -> Galaxy Health Insurance Company Ltd | C58: =IF(A58="Previous Year","April-25","April-26") -> April-26 | D58: 0 | E58: 0 | F58: 0 | G58: 12.27 | H58: 13.09
A59: Previous Year | B59: =IF(A59="Previous Year",B58,A59) -> Galaxy Health Insurance Company Ltd | C59: =IF(A59="Previous Year","April-25","April-26") -> April-25 | D59: 0 | E59: 0 | F59: 0 | G59: 3.06 | H59: 3.38
A60: ManipalCigna Health Insurance Co Ltd | B60: =IF(A60="Previous Year",B59,A60) -> ManipalCigna Health Insurance Co Ltd | C60: =IF(A60="Previous Year","April-25","April-26") -> April-26 | D60: 0 | E60: 0 | F60: 0 | G60: 274.14 | H60: 279.98
A61: Previous Year | B61: =IF(A61="Previous Year",B60,A61) -> ManipalCigna Health Insurance Co Ltd | C61: =IF(A61="Previous Year","April-25","April-26") -> April-25 | D61: 0 | E61: 0 | F61: 0 | G61: 180.61 | H61: 183.78
A62: Narayana Health Insurance Ltd | B62: =IF(A62="Previous Year",B61,A62) -> Narayana Health Insurance Ltd | C62: =IF(A62="Previous Year","April-25","April-26") -> April-26 | D62: 0 | E62: 0 | F62: 0 | G62: 17.91 | H62: 17.91
A63: Previous Year | B63: =IF(A63="Previous Year",B62,A63) -> Narayana Health Insurance Ltd | C63: =IF(A63="Previous Year","April-25","April-26") -> April-25 | D63: 0 | E63: 0 | F63: 0 | G63: 0.4 | H63: 0.4
A64: Star Health & Allied Insurance Co Ltd | B64: =IF(A64="Previous Year",B63,A64) -> Star Health & Allied Insurance Co Ltd | C64: =IF(A64="Previous Year","April-25","April-26") -> April-26 | D64: 0 | E64: 0 | F64: 0 | G64: 1255.65 | H64: 1264.54
A65: Previous Year | B65: =IF(A65="Previous Year",B64,A65) -> Star Health & Allied Insurance Co Ltd | C65: =IF(A65="Previous Year","April-25","April-26") -> April-25 | D65: 0 | E65: 0 | F65: 0 | G65: 1050.55 | H65: 1060.16
A66: Agriculture Insurance Co Of India Ltd | B66: =IF(A66="Previous Year",#REF!,A66) -> Agriculture Insurance Co Of India Ltd | C66: =IF(A66="Previous Year","April-25","April-26") -> April-26 | D66: 0 | E66: 0 | F66: 0 | G66: 0 | H66: 16.48
A67: Previous Year | B67: =IF(A67="Previous Year",B66,A67) -> Agriculture Insurance Co Of India Ltd | C67: =IF(A67="Previous Year","April-25","April-26") -> April-25 | D67: 0 | E67: 0 | F67: 0 | G67: 0 | H67: 5.78
A68: ECGC Ltd | B68: =IF(A68="Previous Year",B67,A68) -> ECGC Ltd | C68: =IF(A68="Previous Year","April-25","April-26") -> April-26 | D68: 0 | E68: 0 | F68: 0 | G68: 0 | H68: 106.47
A69: Previous Year | B69: =IF(A69="Previous Year",B68,A69) -> ECGC Ltd | C69: =IF(A69="Previous Year","April-25","April-26") -> April-25 | D69: 0 | E69: 0 | F69: 0 | G69: 0 | H69: 87.66

Sheet Raw_IRDAI
A1: Raw IRDAI Annual Report Extract
A3: Table I.14: Segment-wise Incurred Claims Ratio of General, Health and Specialised Insurers
A5: Segment | B5: Public_2023_24 | C5: Private_2023_24 | D5: Standalone_Health_2023_24 | E5: Specialised_2023_24 | F5: Total_2023_24 | G5: Public_2024_25 | H5: Private_2024_25 | I5: Standalone_Health_2024_25 | J5: Specialised_2024_25 | K5: Total_2024_25
A6: Fire | B6: 83.46 | C6: 69.67 | D6: NA | E6: NA | F6: 78.33 | G6: 78.07 | H6: 65 | I6: NA | J6: NA | K6: 72.93
A7: Marine | B7: 54.01 | C7: 83.5 | D7: NA | E7: NA | F7: 72.39 | G7: 56.79 | H7: 84.03 | I7: NA | J7: NA | K7: 73.63
A8: Motor | B8: 99.57 | C8: 73.3 | D8: NA | E8: NA | F8: 81.98 | G8: 107.94 | H8: 74.62 | I8: NA | J8: NA | K8: 85.51
A9: Health | B9: 103.16 | C9: 83.49 | D9: 63.63 | E9: NA | F9: 86.35 | G9: 99.84 | H9: 83.46 | I9: 68.06 | J9: NA | K9: 85.34
A10: Others | B10: 75.26 | C10: 74.98 | D10: NA | E10: 66.58 | F10: 72.78 | G10: 67.03 | H10: 77.2 | I10: NA | J10: 54.99 | K10: 68.62
A11: Total | B11: 97.23 | C11: 76.49 | D11: 63.63 | E11: 66.58 | F11: 82.52 | G11: 97.3 | H11: 77.5 | I11: 68.06 | J11: 54.99 | K11: 82.88

Sheet Raw_ICICI_NL4
A1: Raw ICICI Lombard NL-4 Premium Extract
A3: Source: ICICI Lombard Form NL-4 Premium Schedule; values in ₹ lakhs
A5: Segment | B5: FY2024_25_Gross_Direct_Premium | C5: FY2025_26_Gross_Direct_Premium | D5: FY2024_25_Net_Earned_Premium | E5: FY2025_26_Net_Earned_Premium | F5: Metric_Source | G5: Project_Use
A6: Fire | B6: 316669 | C6: 340650 | D6: 65144 | E6: 69024 | F6: ICICI Lombard NL-4 Premium Schedule | G6: Premium base and pricing volume check
A7: Total Marine | B7: 88196 | C7: 90981 | D7: 60739 | E7: 62423 | F7: ICICI Lombard NL-4 Premium Schedule | G7: Marine premium and earned premium base
A8: Total Motor | B8: 1073983 | C8: 1155200 | D8: 1004969 | E8: 1102482 | F8: ICICI Lombard NL-4 Premium Schedule | G8: Motor pricing and claim-ratio denominator
A9: Total Health | B9: 767288 | C9: 907620 | D9: 701523 | E9: 841201 | F9: ICICI Lombard NL-4 Premium Schedule | G9: Health pricing and claim-ratio denominator
A10: Grand Total | B10: 2683336 | C10: 2871246 | D10: 1980020 | E10: 2226357 | F10: ICICI Lombard NL-4 Premium Schedule | G10: Company-level disclosed premium base; not the sum of only selected rows
A12: Note: Selected business lines do not add up to Grand Total because ICICI Lombard’s Grand Total includes the full miscellaneous block, including Motor, Health, Personal Accident, Travel, Workmen’s Compensation, Liability, Engineering, Aviation, Crop/Weather, Credit and other miscellaneous segments. Grand Total is retained as the company-level disclosed total.

Sheet Raw_ICICI_NL5
A1: Raw ICICI Lombard NL-5 Claims Extract
A3: Source: ICICI Lombard Form NL-5 Claims Schedule; values in ₹ lakhs
A5: Segment | B5: FY2024_25_Net_Incurred_Claims | C5: FY2025_26_Net_Incurred_Claims | D5: Metric_Source | E5: Project_Use
A6: Fire | B6: 30460 | C6: 36288 | D6: ICICI Lombard NL-5 Claims Schedule | E6: Fire claim-ratio numerator
A7: Total Marine | B7: 48444 | C7: 56718 | D7: ICICI Lombard NL-5 Claims Schedule | E7: Marine claim-ratio numerator
A8: Total Motor | B8: 645336 | C8: 730697 | D8: ICICI Lombard NL-5 Claims Schedule | E8: Motor claim-ratio numerator
A9: Total Health | B9: 576922 | C9: 659370 | D9: ICICI Lombard NL-5 Claims Schedule | E9: Health claim-ratio numerator
A10: Grand Total | B10: 1398681 | C10: 1582847 | D10: ICICI Lombard NL-5 Claims Schedule | E10: Company-level disclosed claim-ratio numerator; not the sum of only selected rows
A12: Note: Selected business lines do not add up to Grand Total because ICICI Lombard’s Grand Total includes additional miscellaneous claim segments beyond Fire, Marine, Motor and Health. Grand Total is retained as the company-level disclosed claims figure.

Sheet Raw_ICICI_NL6
A1: Raw ICICI Lombard NL-6 Commission Extract
A3: Source: ICICI Lombard Form NL-6 Commission Schedule; values in ₹ lakhs
A5: Segment | B5: FY2024_25_Gross_Commission | C5: FY2025_26_Gross_Commission | D5: FY2024_25_Net_Commission | E5: FY2025_26_Net_Commission | F5: Metric_Source | G5: Project_Use
A6: Fire | B6: 34624 | C6: 40334 | D6: -35377 | E6: -21496 | F6: ICICI Lombard NL-6 Commission Schedule | G6: Fire commission load check
A7: Total Marine | B7: 11455 | C7: 12389 | D7: 9511 | E7: 9394 | F7: ICICI Lombard NL-6 Commission Schedule | G7: Marine commission load check
A8: Total Motor | B8: 315014 | C8: 362307 | D8: 309970 | E8: 352153 | F8: ICICI Lombard NL-6 Commission Schedule | G8: Motor commission load check
A9: Total Health | B9: 134312 | C9: 140054 | D9: 94578 | E9: 101495 | F9: ICICI Lombard NL-6 Commission Schedule | G9: Health commission load check
A10: Grand Total | B10: 541385 | C10: 605306 | D10: 383803 | E10: 448419 | F10: ICICI Lombard NL-6 Commission Schedule | G10: Company-level disclosed commission load; not the sum of only selected rows
A12: Note: Selected business lines do not add up to Grand Total because ICICI Lombard’s Grand Total includes additional miscellaneous commission segments beyond Fire, Marine, Motor and Health. Grand Total is retained as the company-level disclosed commission figure.

Sheet Raw_ICICI_NL7
A1: Raw ICICI Lombard NL-7 Operating Expenses Extract
A3: Source: ICICI Lombard Form NL-7 Operating Expenses Schedule; values in ₹ lakhs
A5: Segment | B5: FY2024_25_Operating_Expenses | C5: FY2025_26_Operating_Expenses | D5: Metric_Source | E5: Project_Use | F5: Total_Check_Note
A6: Fire | B6: 11032 | C6: 11744 | D6: ICICI Lombard NL-7 Operating Expenses Schedule | E6: Fire expense-load check | F6: Selected row only
A7: Total Marine | B7: 7947 | C7: 8911 | D7: ICICI Lombard NL-7 Operating Expenses Schedule | E7: Marine expense-load check | F7: Selected row only
A8: Total Motor | B8: 125085 | C8: 105427 | D8: ICICI Lombard NL-7 Operating Expenses Schedule | E8: Motor expense-load check | F8: Selected row only
A9: Total Health | B9: 110913 | C9: 145745 | D9: ICICI Lombard NL-7 Operating Expenses Schedule | E9: Health expense-load check | F9: Selected row only
A10: Grand Total | B10: 284484 | C10: 305855 | D10: ICICI Lombard NL-7 Operating Expenses Schedule | E10: Company-level disclosed operating expense; not the sum of only selected rows | F10: Disclosed company-level total
A12: Note: Selected business lines do not add up to Grand Total because ICICI Lombard’s Grand Total includes additional miscellaneous operating expense segments beyond Fire, Marine, Motor and Health. Grand Total is retained as the company-level disclosed operating expense figure.

Sheet Source_Log
A1: Source_Name | B1: Source_Type | C1: Data_Used | D1: Project_Use | E1: File_Saved_As | F1: Download_Status | G1: Extraction_Status | H1: Used_In_Sheets | I1: Notes
A2: GI Council Segment Report | B2: Industry statistics workbook | C2: Segment-wise gross direct premium by insurer and segment | D2: Segment premium growth, insurer ranking, dashboard charts | E2: GI_Council_Segmentwise_GDPI_Latest.xlsx | F2: Downloaded | G2: Extracted and cleaned | H2: Raw_GI_Council, Cleaned_Auto, Analysis, pivot sheets | I2: Used for Apr-25 vs Apr-26 premium comparison and insurer ranking
A3: IRDAI Annual Report 2024-25 | B3: Regulator annual report PDF | C3: Segment-wise incurred claims ratio | D3: Claim-pressure analysis and pricing adequacy interpretation | E3: IRDAI_Annual_Report_2024_25.pdf | F3: Downloaded | G3: Extracted Table I.14 | H3: Raw_IRDAI, IRDAI_ICR_Data | I3: ICR used as claim-pressure indicator
A4: ICICI Lombard NL-4 Premium Schedule | B4: Insurer public disclosure PDF | C4: Gross direct premium and net earned premium | D4: Company-level premium base and claim-ratio denominator | E4: ICICI_Lombard_NL4_Premium_FY2024_25.pdf | F4: Downloaded | G4: Extracted selected segments and disclosed Grand Total | H4: Raw_ICICI_NL4, ICICI_Company_Case | I4: Selected rows do not add to Grand Total
A5: ICICI Lombard NL-5 Claims Schedule | B5: Insurer public disclosure PDF | C5: Net incurred claims | D5: Company-level claim-ratio numerator | E5: ICICI_Lombard_NL5_Claims_Incurred_FY2024_25.pdf | F5: Downloaded | G5: Extracted selected segments and disclosed Grand Total | H5: Raw_ICICI_NL5, ICICI_Company_Case | I5: Selected rows do not add to Grand Total
A6: ICICI Lombard NL-6 Commission Schedule | B6: Insurer public disclosure PDF | C6: Gross commission and net commission | D6: Commission load analysis | E6: ICICI_Lombard_NL6_Commission_FY2024_25.pdf | F6: Downloaded | G6: Extracted selected segments and disclosed Grand Total | H6: Raw_ICICI_NL6, ICICI_Company_Case | I6: Fire net commission is negative due to reinsurance commission effect
A7: ICICI Lombard NL-7 Operating Expenses Schedule | B7: Insurer public disclosure PDF | C7: Operating expenses related to insurance business | D7: Expense load analysis | E7: ICICI_Lombard_NL7_Operating_Expenses_FY2024_25.pdf | F7: Downloaded | G7: Extracted selected segments and disclosed Grand Total | H7: Raw_ICICI_NL7, ICICI_Company_Case | I7: Used for analytical Combined Load, not formal combined ratio
